Traceback (most recent call last):
  File "/usr/local/lib/python3.8/dist-packages/jupyter_cache/executors/utils.py", line 51, in single_nb_execution
    executenb(
  File "/usr/local/lib/python3.8/dist-packages/nbclient/client.py", line 1087, in execute
    return NotebookClient(nb=nb, resources=resources, km=km, **kwargs).execute()
  File "/usr/local/lib/python3.8/dist-packages/nbclient/util.py", line 74, in wrapped
    return just_run(coro(*args, **kwargs))
  File "/usr/local/lib/python3.8/dist-packages/nbclient/util.py", line 53, in just_run
    return loop.run_until_complete(coro)
  File "/usr/lib/python3.8/asyncio/base_events.py", line 616, in run_until_complete
    return future.result()
  File "/usr/local/lib/python3.8/dist-packages/nbclient/client.py", line 540, in async_execute
    await self.async_execute_cell(
  File "/usr/local/lib/python3.8/dist-packages/nbclient/client.py", line 832, in async_execute_cell
    self._check_raise_for_error(cell, exec_reply)
  File "/usr/local/lib/python3.8/dist-packages/nbclient/client.py", line 740, in _check_raise_for_error
    raise CellExecutionError.from_cell_and_msg(cell, exec_reply['content'])
nbclient.exceptions.CellExecutionError: An error occurred while executing the following cell:
------------------
problem = dolfinx.fem.LinearProblem(a, L, bcs=[bc], petsc_options={"ksp_type": "preonly", "pc_type": "lu"})
uh = problem.solve()

import dolfinx.plotting
dolfinx.plotting.plot(uh)

V2 = dolfinx.FunctionSpace(mesh, ("CG", 2))
uex = dolfinx.Function(V2)
uex.interpolate(u_exact)
uex.vector.ghostUpdate(addv=PETSc.InsertMode.INSERT, mode=PETSc.ScatterMode.FORWARD)
error_L2 = dolfinx.fem.assemble_scalar((uh - uex)**2 * ufl.dx)
error_L2 = np.sqrt(MPI.COMM_WORLD.allreduce(error_L2, op=MPI.SUM))

u_vertex_values = uh.compute_point_values()
u_ex_vertex_values = uex.compute_point_values()
error_max = np.max(np.abs(u_vertex_values - u_ex_vertex_values))
error_max = MPI.COMM_WORLD.allreduce(error_max, op=MPI.MAX)
print("Error_L2 = {0:.2e}".format(error_L2))
print("Error_max = {0:.2e}".format(error_max))
------------------

[0;31m---------------------------------------------------------------------------[0m
[0;31mModuleNotFoundError[0m                       Traceback (most recent call last)
[0;32m<ipython-input-4-19a9df976c43>[0m in [0;36m<module>[0;34m[0m
[1;32m      2[0m [0muh[0m [0;34m=[0m [0mproblem[0m[0;34m.[0m[0msolve[0m[0;34m([0m[0;34m)[0m[0;34m[0m[0;34m[0m[0m
[1;32m      3[0m [0;34m[0m[0m
[0;32m----> 4[0;31m [0;32mimport[0m [0mdolfinx[0m[0;34m.[0m[0mplotting[0m[0;34m[0m[0;34m[0m[0m
[0m[1;32m      5[0m [0mdolfinx[0m[0;34m.[0m[0mplotting[0m[0;34m.[0m[0mplot[0m[0;34m([0m[0muh[0m[0;34m)[0m[0;34m[0m[0;34m[0m[0m
[1;32m      6[0m [0;34m[0m[0m

[0;31mModuleNotFoundError[0m: No module named 'dolfinx.plotting'
ModuleNotFoundError: No module named 'dolfinx.plotting'

